<!-- See LICENSE.md for legal notices. LICENSE.md must be kept together with this file. -->
<mujoco>
    <body name="base_link" pos="0 0 0" quat="1 0 0 0">
        <!-- Left UR5 -->
        <geom name="ur5_left:link0" type="mesh" mesh="link0" pos="1.2 -0.254 1.3462" quat="-0.3826834 -0.9238795 0 0" class="ur:visual"/>
        <!-- link1 pos = (0, 0, 0.0123) * link0 quat
             link1 quat = link0 quat -->
        <body name="ur5_left:link1" pos="1.2 -0.2691 1.3311" quat="-0.3826834 -0.9238795 0 0">
            <joint name="ur5_left:joint0" pos="0 0 0" axis="0 0 1" limited="true" range="-3.1415 3.1415" armature="0.1" damping="200"/>
            <inertial pos="0 -0.02561 0.00193" mass="3.761" diaginertia="0.1 0.1 0.1"/>
            <geom name="ur5_left:link1_connector" type="mesh" mesh="link1_connector" pos="0 0 0" material="black" class="ur:visual"/>
            <geom name="ur5_left:link1" type="mesh" mesh="link1" pos="0 0 0.008" material="grey" class="ur:visual"/>
            <geom name="ur5_left:link1_cap" type="mesh" mesh="link1_cap" pos="0 0 .1025" material="blue" class="ur:visual"/>
            <geom name="ur5_left:c_link1_connector" type="mesh" mesh="link1_connector" pos="0 0 0" material="black" class="ur:collision"/>
            <geom name="ur5_left:c_link1" type="mesh" mesh="link1" pos="0 0 0.008" material="grey" class="ur:collision"/>
            <geom name="ur5_left:c_link1_cap" type="mesh" mesh="link1_cap" pos="0 0 .1025" material="blue" class="ur:collision"/>

            <body name="ur5_left:link2" pos="-0.0663 0 0.0679">
                <joint name="ur5_left:joint1" pos="0 0 0" axis="-1 0 0" limited="true" range="-3.1415 3.1415" armature="0.1" damping="200"/>
                <inertial pos="-0.04706 0 0.2125" mass="8.058" diaginertia="0.1 0.1 0.1"/>
                <geom name="ur5_left:link2_connector" type="mesh" mesh="link2_connector" pos="0 0 0" material="black" class="ur:visual"/>
                <geom name="ur5_left:link2" type="mesh" mesh="link2" pos="-0.008 0 0" material="grey" class="ur:visual"/>
                <geom name="ur5_left:link2_cap" type="mesh" mesh="link2_cap" pos="-0.1015 0 -0.0025" material="blue" class="ur:visual"/>
                <geom name="ur5_left:link2_tube" type="mesh" mesh="link2_tube" pos="-0.0679 0 0.066" material="silver" class="ur:visual"/>
                <geom name="ur5_left:c_link2_connector" type="mesh" mesh="link2_connector" pos="0 0 0" material="black" class="ur:collision"/>
                <geom name="ur5_left:c_link2" type="mesh" mesh="link2" pos="-0.008 0 0" material="grey" class="ur:collision"/>
                <geom name="ur5_left:c_link2_cap" type="mesh" mesh="link2_cap" pos="-0.1015 0 -0.0025" material="blue" class="ur:collision"/>
                <geom name="ur5_left:c_link2_tube" type="mesh" mesh="link2_tube" pos="-0.0679 0 0.066" material="silver" class="ur:collision"/>

                <body name="ur5_left:link3" pos="-0.008 0 0.425">
                    <joint name="ur5_left:joint2" pos="0 0 0" axis="1 0 0" limited="true" range="-3.1415 3.1415" armature="0.1" damping="200"/>
                    <inertial pos="0.0478 0 0.15" mass="2.846" diaginertia="0.1 0.1 0.1"/>
                    <geom name="ur5_left:link3a_connector" type="mesh" mesh="link3a_connector" pos="0 0 0" material="black" class="ur:visual"/>
                    <geom name="ur5_left:link3a" type="mesh" mesh="link3a" pos="0.008 0 0" material="grey" class="ur:visual"/>
                    <geom name="ur5_left:link3_tube" type="mesh" mesh="link3_tube" pos="0.059 0 0.066" material="silver" class="ur:visual"/>
                    <geom name="ur5_left:link3b_connector" type="mesh" mesh="link3b_connector" pos="0.059 0 0.3418" material="black" class="ur:visual"/>
                    <geom name="ur5_left:link3b_connector2" type="mesh" mesh="link3b_connector2" pos="0.059 0 0.34" material="grey" class="ur:visual"/>
                    <geom name="ur5_left:link3b" type="mesh" mesh="link3b" pos="0.059 0 0.347" material="grey" class="ur:visual"/>
                    <geom name="ur5_left:link3_cap" type="mesh" mesh="link3_cap" pos="0.0837 0 0.392" material="blue" class="ur:visual"/>
                    <geom name="ur5_left:c_link3a_connector" type="mesh" mesh="link3a_connector" pos="0 0 0" material="black" class="ur:collision"/>
                    <geom name="ur5_left:c_link3a" type="mesh" mesh="link3a" pos="0.008 0 0" material="grey" class="ur:collision"/>
                    <geom name="ur5_left:c_link3_tube" type="mesh" mesh="link3_tube" pos="0.059 0 0.066" material="silver" class="ur:collision"/>
                    <geom name="ur5_left:c_link3b_connector" type="mesh" mesh="link3b_connector" pos="0.059 0 0.3418" material="black" class="ur:collision"/>
                    <geom name="ur5_left:c_link3b_connector2" type="mesh" mesh="link3b_connector2" pos="0.059 0 0.34" material="grey" class="ur:collision"/>
                    <geom name="ur5_left:c_link3b" type="mesh" mesh="link3b" pos="0.059 0 0.347" material="grey" class="ur:collision"/>
                    <geom name="ur5_left:c_link3_cap" type="mesh" mesh="link3_cap" pos="0.0837 0 0.392" material="blue" class="ur:collision"/>

                    <body name="ur5_left:link4" pos="0.0173 0 0.3922">
                        <joint name="ur5_left:joint3" pos="0 0 0" axis="-1 0 0" limited="true" range="-3.1415 3.1415" armature="0.1" damping="15"/>
                        <inertial pos="-0.05796 -0.0018 0" mass="1.37" diaginertia="0.1 0.1 0.1"/>
                        <geom name="ur5_left:link4_connector" type="mesh" mesh="link4_connector" pos="0 0 0" material="black" class="ur:visual"/>
                        <geom name="ur5_left:link4" type="mesh" mesh="link4" pos="-0.008 0 0" material="grey" class="ur:visual"/>
                        <geom name="ur5_left:link4_cap" type="mesh" mesh="link4_cap" pos="-0.05325 0 -0.0247" material="blue" class="ur:visual"/>
                        <geom name="ur5_left:c_link4_connector" type="mesh" mesh="link4_connector" pos="0 0 0" material="black" class="ur:collision"/>
                        <geom name="ur5_left:c_link4" type="mesh" mesh="link4" pos="-0.008 0 0" material="grey" class="ur:collision"/>
                        <geom name="ur5_left:c_link4_cap" type="mesh" mesh="link4_cap" pos="-0.05325 0 -0.0247" material="blue" class="ur:collision"/>

                        <body name="ur5_left:link5" pos="-0.05325 0 0.04165">
                            <joint name="ur5_left:joint4" pos="0 0 0" axis="0 0 1" limited="true" range="-3.1415 3.1415" armature="0.1" damping="15"/>
                            <inertial pos="0.0018 0 0.01634" mass="1.3" diaginertia="0.1 0.1 0.1"/>
                            <geom name="ur5_left:link5_connector" type="mesh" mesh="link5_connector" pos="0 0 0" material="black" class="ur:visual"/>
                            <geom name="ur5_left:link5" type="mesh" mesh="link5" pos="0 0 0.0079" material="grey" class="ur:visual"/>
                            <geom name="ur5_left:link5_cap" type="mesh" mesh="link5_cap" pos="0.025 0 0.053" material="blue" class="ur:visual"/>
                            <geom name="ur5_left:c_link5_connector" type="mesh" mesh="link5_connector" pos="0 0 0" material="black" class="ur:collision"/>
                            <geom name="ur5_left:c_link5" type="mesh" mesh="link5" pos="0 0 0.0079" material="grey" class="ur:collision"/>
                            <geom name="ur5_left:c_link5_cap" type="mesh" mesh="link5_cap" pos="0.025 0 0.053" material="blue" class="ur:collision"/>

                            <body name="ur5_left:link6" pos="-0.04165 0 0.05305">
                                <joint name="ur5_left:joint5" pos="0 0 0" axis="-1 0 0" limited="true" range="-3.1415 3.1415" armature="0.1" damping="15"/>
                                <inertial pos="-0.038841 0 0" mass="0.365" diaginertia="0.1 0.1 0.1"/>
                                <geom name="ur5_left:link6_connector" type="mesh" mesh="link6_connector" pos="0 0 0" material="black" class="ur:visual"/>
                                <geom name="ur5_left:link6" type="mesh" mesh="link6" pos="-0.008 0 0" material="silver" class="ur:visual"/>                   
                            
                                <!-- Left AbilityHand -->
                                <body name="ability_left:hand_mount" pos="-0.04 0 0" gravcomp="0" euler="0 -1.5708 0">
                                    <inertial pos="0.00861632 0.00238111 0.0202366" quat="0.708112 -0.237177 -0.181781 0.63975" mass="0.6" diaginertia="0.00107598 0.00107535 0.000893814"/>
                                    
                                    <geom name="ability_left:wrist_mesh" type="mesh" contype="0" conaffinity="0" group="1" density="0" mesh="ability_left:wristmesh"/>
                                    <geom name="ability_left:palm_mesh" pos="0.0240477 0.00378125 0.0323296" quat="0.0442297 0.00061027 0.999021 2.70192e-05" type="mesh" contype="0" conaffinity="0" group="1" density="0" mesh="ability_left:FB_palm_ref"/>
                                    <geom name="ability_left:palm_hull" pos="0.0240477 0.00378125 0.0323296" quat="0.0442297 0.00061027 0.999021 2.70192e-05" type="mesh" mesh="ability_left:palm_hull"/>
                                    <body name="ability_left:index_L1" pos="0.0279216 -0.00927034 0.0958706" quat="-0.714459 -0.129917 0.685906 0.0469401" gravcomp="0">
                                        <inertial pos="0.0224191 -0.000157982 -1.31987e-05" quat="-0.00406251 0.706621 0.00934715 0.707518" mass="0.00635888" diaginertia="3.81765e-06 3.69601e-06 2.96432e-07"/>
                                        <joint name="ability_left:index_q1" pos="0 0 0" axis="0 0 1" limited="true" range="0 2.0944" damping="0.001" frictionloss="0.001"/>
                                        <geom name="ability_left:index_mesh_1" pos="0.0384727 0.0032577 0" quat="0.999108 0 0 0.0422244" type="mesh" contype="0" conaffinity="0" group="1" density="0" mesh="ability_left:idx-F1"/>
                                        <geom name="ability_left:index_hull_1" pos="0.0384727 0.0032577 0" quat="0.999108 0 0 0.0422244" type="mesh" mesh="ability_left:idx-F1-hull"/>
                                        <body name="ability_left:index_L2" pos="0.0384727 0.0032577 0" quat="0.999108 0 0 0.0422244" gravcomp="0">
                                        <inertial pos="0.0133682 -0.00875392 -2.886e-05" quat="-0.161363 0.673074 0.216775 0.688434" mass="0.00645" diaginertia="2.64645e-06 2.63553e-06 1.71391e-07"/>
                                        <joint name="ability_left:index_q2" pos="0 0 0" axis="0 0 1" limited="true" range="0 2.6586" damping="0.001" frictionloss="0.001"/>
                                        <geom name="ability_left:index_mesh_2" pos="0.0091241 0 0" type="mesh" contype="0" conaffinity="0" group="1" density="0" mesh="ability_left:idx-F2"/>
                                        <geom name="ability_left:index_hull_2" pos="0.0091241 0 0" type="mesh" mesh="ability_left:idx-F2-hull"/>
                                        </body>
                                    </body>
                                    <body name="ability_left:middle_L1" pos="0.00841718 -0.0115172 0.0990634" quat="-0.698395 -0.103508 0.704562 0.0715738" gravcomp="0">
                                        <inertial pos="0.0224191 -0.000157982 -1.31987e-05" quat="-0.00406251 0.706621 0.00934715 0.707518" mass="0.00635888" diaginertia="3.81765e-06 3.69601e-06 2.96432e-07"/>
                                        <joint name="ability_left:middle_q1" pos="0 0 0" axis="0 0 1" limited="true" range="0 2.0944" damping="0.001" frictionloss="0.001"/>
                                        <geom name="ability_left:middle_mesh_1" pos="0.0384727 0.0032577 0" quat="0.999108 0 0 0.0422244" type="mesh" contype="0" conaffinity="0" group="1" density="0" mesh="ability_left:idx-F1"/>
                                        <geom name="ability_left:middle_hull_1" pos="0.0384727 0.0032577 0" quat="0.999108 0 0 0.0422244" type="mesh" mesh="ability_left:idx-F1-hull"/>
                                        <body name="ability_left:middle_L2" pos="0.0384727 0.0032577 0" quat="0.999108 0 0 0.0422244" gravcomp="0">
                                        <inertial pos="0.0133682 -0.00875392 -2.886e-05" quat="-0.161363 0.673074 0.216775 0.688434" mass="0.00645" diaginertia="2.64645e-06 2.63553e-06 1.71391e-07"/>
                                        <joint name="ability_left:middle_q2" pos="0 0 0" axis="0 0 1" limited="true" range="0 2.6586" damping="0.001" frictionloss="0.001"/>
                                        <geom name="ability_left:middle_mesh_2" pos="0.0091241 0 0" type="mesh" contype="0" conaffinity="0" group="1" density="0" mesh="ability_left:idx-F2"/>
                                        <geom name="ability_left:middle_hull_2" pos="0.0091241 0 0" type="mesh" mesh="ability_left:idx-F2-hull"/>
                                        </body>
                                    </body>
                                    <body name="ability_left:ring_L1" pos="-0.0117529 -0.0103946 0.0967038" quat="-0.681173 -0.0769649 0.721351 0.0986547" gravcomp="0">
                                        <inertial pos="0.0224191 -0.000157982 -1.31987e-05" quat="-0.00406251 0.706621 0.00934715 0.707518" mass="0.00635888" diaginertia="3.81765e-06 3.69601e-06 2.96432e-07"/>
                                        <joint name="ability_left:ring_q1" pos="0 0 0" axis="0 0 1" limited="true" range="0 2.0944" damping="0.001" frictionloss="0.001"/>
                                        <geom name="ability_left:ring_mesh_1" pos="0.0384727 0.0032577 0" quat="0.999108 0 0 0.0422244" type="mesh" contype="0" conaffinity="0" group="1" density="0" mesh="ability_left:idx-F1"/>
                                        <geom name="ability_left:ring_hull_1" pos="0.0384727 0.0032577 0" quat="0.999108 0 0 0.0422244" type="mesh" mesh="ability_left:idx-F1-hull"/>
                                        <body name="ability_left:ring_L2" pos="0.0384727 0.0032577 0" quat="0.999108 0 0 0.0422244" gravcomp="0">
                                        <inertial pos="0.0133682 -0.00875392 -2.886e-05" quat="-0.161363 0.673074 0.216775 0.688434" mass="0.00645" diaginertia="2.64645e-06 2.63553e-06 1.71391e-07"/>
                                        <joint name="ability_left:ring_q2" pos="0 0 0" axis="0 0 1" limited="true" range="0 2.6586" damping="0.001" frictionloss="0.001"/>
                                        <geom name="ability_left:ring_mesh_2" pos="0.0091241 0 0" type="mesh" contype="0" conaffinity="0" group="1" density="0" mesh="ability_left:idx-F2"/>
                                        <geom name="ability_left:ring_hull_2" pos="0.0091241 0 0" type="mesh" mesh="ability_left:idx-F2-hull"/>
                                        </body>
                                    </body>
                                    <body name="ability_left:pinky_L1" pos="-0.0308633 -0.00716283 0.0907346" quat="-0.681748 -0.0544096 0.719226 0.122363" gravcomp="0">
                                        <inertial pos="0.0224191 -0.000157982 -1.31987e-05" quat="-0.00406251 0.706621 0.00934715 0.707518" mass="0.00635888" diaginertia="3.81765e-06 3.69601e-06 2.96432e-07"/>
                                        <joint name="ability_left:pinky_q1" pos="0 0 0" axis="0 0 1" limited="true" range="0 2.0944" damping="0.001" frictionloss="0.001"/>
                                        <geom name="ability_left:pinky_mesh_1" pos="0.0384727 0.0032577 0" quat="0.999108 0 0 0.0422244" type="mesh" contype="0" conaffinity="0" group="1" density="0" mesh="ability_left:idx-F1"/>
                                        <geom name="ability_left:pinky_hull_1" pos="0.0384727 0.0032577 0" quat="0.999108 0 0 0.0422244" type="mesh" mesh="ability_left:idx-F1-hull"/>
                                        <body name="ability_left:pinky_L2" pos="0.0384727 0.0032577 0" quat="0.999108 0 0 0.0422244" gravcomp="0">
                                        <inertial pos="0.0133682 -0.00875392 -2.886e-05" quat="-0.161363 0.673074 0.216775 0.688434" mass="0.00645" diaginertia="2.64645e-06 2.63553e-06 1.71391e-07"/>
                                        <joint name="ability_left:pinky_q2" pos="0 0 0" axis="0 0 1" limited="true" range="0 2.6586" damping="0.001" frictionloss="0.001"/>
                                        <geom name="ability_left:pinky_mesh_2" pos="0.0091241 0 0" type="mesh" contype="0" conaffinity="0" group="1" density="0" mesh="ability_left:idx-F2"/>
                                        <geom name="ability_left:pinky_hull_2" pos="0.0091241 0 0" type="mesh" mesh="ability_left:idx-F2-hull"/>
                                        </body>
                                    </body>
                                    <body name="ability_left:thumb_L1" pos="0.0240477 0.00378125 0.0323296" quat="-0.00419696 0.994514 -0.0947972 0.0440301" gravcomp="0">
                                        <inertial pos="0.014606 -0.00189085 -0.00311554" quat="0.306728 0.531258 0.293089 0.733336" mass="0.00268342" diaginertia="8.14795e-07 7.42718e-07 1.14409e-07"/>
                                        <joint name="ability_left:thumb_q1" pos="0 0 0" axis="0 0 1" limited="true" range="-2.0944 0" damping="0.001" frictionloss="0.001"/>
                                        <geom name="ability_left:thumb_mesh_1" pos="0.0278284 0 -0.0147507" quat="-0.608761 0.793353 0 0" type="mesh" contype="0" conaffinity="0" group="1" density="0" mesh="ability_left:thumb-F1"/>
                                        <geom name="ability_left:thumb_hull_1" pos="0.0278284 0 -0.0147507" quat="-0.608761 0.793353 0 0" type="mesh" mesh="ability_left:thumb-F1-hull"/>
                                        <body name="ability_left:thumb_L2" pos="0.0278284 0 -0.0147507" quat="-0.608761 0.793353 0 0" gravcomp="0">
                                        <inertial pos="0.0300205 0.00559476 -0.00415044" quat="0.00721249 0.656735 -0.223684 0.720148" mass="0.0055" diaginertia="1.80207e-05 1.70892e-05 2.87855e-06"/>
                                        <joint name="ability_left:thumb_q2" pos="0 0 0" axis="0 0 1" limited="true" range="0 2.0944" damping="0.001" frictionloss="0.001"/>
                                        <geom name="ability_left:thumb_mesh_2" pos="0.0651867 0.0233402 -0.00393483" quat="3.21978e-07 0.985259 0.171069 5.59046e-08" type="mesh" contype="0" conaffinity="0" group="1" density="0" mesh="ability_left:thumb-F2"/>
                                        <geom name="ability_left:thumb_hull_2" pos="0.0651867 0.0233402 -0.00393483" quat="3.21978e-07 0.985259 0.171069 5.59046e-08" type="mesh" mesh="ability_left:thumb-F2-hull"/>
                                        </body>
                                    </body>
                                </body>
                            </body>
                        </body>
                    </body>
                </body>
            </body>
        </body>

        <!-- Right UR5 -->
        <geom name="ur5_right:link0" type="mesh" mesh="link0" pos="1.2 0.254 1.3462" quat="0.3826834 -0.9238795 0 0" class="ur:visual"/>
        <!-- link1 pos = (0, 0, 0.0123) * link0 quat
             link1 quat = link0 quat -->
        <body name="ur5_right:link1" pos="1.2 0.2691 1.3311" quat="0.3826834 -0.9238795 0 0">
            <joint name="ur5_right:joint0" pos="0 0 0" axis="0 0 1" limited="true" range="-3.1415 3.1415" armature="0.1" damping="200"/>
            <inertial pos="0 -0.02561 0.00193" mass="3.761" diaginertia="0.1 0.1 0.1"/>
            <geom name="ur5_right:link1_connector" type="mesh" mesh="link1_connector" pos="0 0 0" material="black" class="ur:visual"/>
            <geom name="ur5_right:link1" type="mesh" mesh="link1" pos="0 0 0.008" material="grey" class="ur:visual"/>
            <geom name="ur5_right:link1_cap" type="mesh" mesh="link1_cap" pos="0 0 .1025" material="blue" class="ur:visual"/>
            <geom name="ur5_right:c_link1_connector" type="mesh" mesh="link1_connector" pos="0 0 0" material="black" class="ur:collision"/>
            <geom name="ur5_right:c_link1" type="mesh" mesh="link1" pos="0 0 0.008" material="grey" class="ur:collision"/>
            <geom name="ur5_right:c_link1_cap" type="mesh" mesh="link1_cap" pos="0 0 .1025" material="blue" class="ur:collision"/>
        
            <body name="ur5_right:link2" pos="-0.0663 0 0.0679">
                <joint name="ur5_right:joint1" pos="0 0 0" axis="-1 0 0" limited="true" range="-3.1415 3.1415" armature="0.1" damping="200"/>
                <inertial pos="-0.04706 0 0.2125" mass="8.058" diaginertia="0.1 0.1 0.1"/>
                <geom name="ur5_right:link2_connector" type="mesh" mesh="link2_connector" pos="0 0 0" material="black" class="ur:visual"/>
                <geom name="ur5_right:link2" type="mesh" mesh="link2" pos="-0.008 0 0" material="grey" class="ur:visual"/>
                <geom name="ur5_right:link2_cap" type="mesh" mesh="link2_cap" pos="-0.1015 0 -0.0025" material="blue" class="ur:visual"/>
                <geom name="ur5_right:link2_tube" type="mesh" mesh="link2_tube" pos="-0.0679 0 0.066" material="silver" class="ur:visual"/>
                <geom name="ur5_right:c_link2_connector" type="mesh" mesh="link2_connector" pos="0 0 0" material="black" class="ur:collision"/>
                <geom name="ur5_right:c_link2" type="mesh" mesh="link2" pos="-0.008 0 0" material="grey" class="ur:collision"/>
                <geom name="ur5_right:c_link2_cap" type="mesh" mesh="link2_cap" pos="-0.1015 0 -0.0025" material="blue" class="ur:collision"/>
                <geom name="ur5_right:c_link2_tube" type="mesh" mesh="link2_tube" pos="-0.0679 0 0.066" material="silver" class="ur:collision"/>

                <body name="ur5_right:link3" pos="-0.008 0 0.425">
                    <joint name="ur5_right:joint2" pos="0 0 0" axis="1 0 0" limited="true" range="-3.1415 3.1415" armature="0.1" damping="200"/>
                    <inertial pos="0.0478 0 0.15" mass="2.846" diaginertia="0.1 0.1 0.1"/>
                    <geom name="ur5_right:link3a_connector" type="mesh" mesh="link3a_connector" pos="0 0 0" material="black" class="ur:visual"/>
                    <geom name="ur5_right:link3a" type="mesh" mesh="link3a" pos="0.008 0 0" material="grey" class="ur:visual"/>
                    <geom name="ur5_right:link3_tube" type="mesh" mesh="link3_tube" pos="0.059 0 0.066" material="silver" class="ur:visual"/>
                    <geom name="ur5_right:link3b_connector" type="mesh" mesh="link3b_connector" pos="0.059 0 0.3418" material="black" class="ur:visual"/>
                    <geom name="ur5_right:link3b_connector2" type="mesh" mesh="link3b_connector2" pos="0.059 0 0.34" material="grey" class="ur:visual"/>
                    <geom name="ur5_right:link3b" type="mesh" mesh="link3b" pos="0.059 0 0.347" material="grey" class="ur:visual"/>
                    <geom name="ur5_right:link3_cap" type="mesh" mesh="link3_cap" pos="0.0837 0 0.392" material="blue" class="ur:visual"/>
                    <geom name="ur5_right:c_link3a_connector" type="mesh" mesh="link3a_connector" pos="0 0 0" material="black" class="ur:collision"/>
                    <geom name="ur5_right:c_link3a" type="mesh" mesh="link3a" pos="0.008 0 0" material="grey" class="ur:collision"/>
                    <geom name="ur5_right:c_link3_tube" type="mesh" mesh="link3_tube" pos="0.059 0 0.066" material="silver" class="ur:collision"/>
                    <geom name="ur5_right:c_link3b_connector" type="mesh" mesh="link3b_connector" pos="0.059 0 0.3418" material="black" class="ur:collision"/>
                    <geom name="ur5_right:c_link3b_connector2" type="mesh" mesh="link3b_connector2" pos="0.059 0 0.34" material="grey" class="ur:collision"/>
                    <geom name="ur5_right:c_link3b" type="mesh" mesh="link3b" pos="0.059 0 0.347" material="grey" class="ur:collision"/>
                    <geom name="ur5_right:c_link3_cap" type="mesh" mesh="link3_cap" pos="0.0837 0 0.392" material="blue" class="ur:collision"/>

                    <body name="ur5_right:link4" pos="0.0173 0 0.3922">
                        <joint name="ur5_right:joint3" pos="0 0 0" axis="-1 0 0" limited="true" range="-3.1415 3.1415" armature="0.1" damping="15"/>
                        <inertial pos="-0.05796 -0.0018 0" mass="1.37" diaginertia="0.1 0.1 0.1"/>
                        <geom name="ur5_right:link4_connector" type="mesh" mesh="link4_connector" pos="0 0 0" material="black" class="ur:visual"/>
                        <geom name="ur5_right:link4" type="mesh" mesh="link4" pos="-0.008 0 0" material="grey" class="ur:visual"/>
                        <geom name="ur5_right:link4_cap" type="mesh" mesh="link4_cap" pos="-0.05325 0 -0.0247" material="blue" class="ur:visual"/>
                        <geom name="ur5_right:c_link4_connector" type="mesh" mesh="link4_connector" pos="0 0 0" material="black" class="ur:collision"/>
                        <geom name="ur5_right:c_link4" type="mesh" mesh="link4" pos="-0.008 0 0" material="grey" class="ur:collision"/>
                        <geom name="ur5_right:c_link4_cap" type="mesh" mesh="link4_cap" pos="-0.05325 0 -0.0247" material="blue" class="ur:collision"/>

                        <body name="ur5_right:link5" pos="-0.05325 0 0.04165">
                            <joint name="ur5_right:joint4" pos="0 0 0" axis="0 0 1" limited="true" range="-3.1415 3.1415" armature="0.1" damping="15"/>
                            <inertial pos="0.0018 0 0.01634" mass="1.3" diaginertia="0.1 0.1 0.1"/>
                            <geom name="ur5_right:link5_connector" type="mesh" mesh="link5_connector" pos="0 0 0" material="black" class="ur:visual"/>
                            <geom name="ur5_right:link5" type="mesh" mesh="link5" pos="0 0 0.0079" material="grey" class="ur:visual"/>
                            <geom name="ur5_right:link5_cap" type="mesh" mesh="link5_cap" pos="0.025 0 0.053" material="blue" class="ur:visual"/>
                            <geom name="ur5_right:c_link5_connector" type="mesh" mesh="link5_connector" pos="0 0 0" material="black" class="ur:collision"/>
                            <geom name="ur5_right:c_link5" type="mesh" mesh="link5" pos="0 0 0.0079" material="grey" class="ur:collision"/>
                            <geom name="ur5_right:c_link5_cap" type="mesh" mesh="link5_cap" pos="0.025 0 0.053" material="blue" class="ur:collision"/>

                            <body name="ur5_right:link6" pos="-0.04165 0 0.05305">
                                <joint name="ur5_right:joint5" pos="0 0 0" axis="-1 0 0" limited="true" range="-3.1415 3.1415" armature="0.1" damping="15"/>
                                <inertial pos="-0.038841 0 0" mass="0.365" diaginertia="0.1 0.1 0.1"/>
                                <geom name="ur5_right:link6_connector" type="mesh" mesh="link6_connector" pos="0 0 0" material="black" class="ur:visual"/>
                                <geom name="ur5_right:link6" type="mesh" mesh="link6" pos="-0.008 0 0" material="silver" class="ur:visual"/>                   
                            
                                <!-- Right AbilityHand -->
                                <body name="ability_right:hand_mount" pos="-0.04 0 0" gravcomp="0" euler="0 -1.5708 0">
                                    <inertial pos="-0.0234454 0.00234459 0.0228783" quat="0.386518 0.610261 0.592118 0.357185" mass="0.6" diaginertia="0.00257632 0.00257632 0.00178617"/>
                                    
                                    <geom name="ability_right:wrist_mesh" type="mesh" contype="0" conaffinity="0" group="1" density="0" mesh="ability_right:wristmesh"/>
                                    <geom name="ability_right:palm_mesh" pos="-0.0240477 0.00378125 0.0323296" quat="0.0442297 0.00061027 -0.999021 -2.70192e-05" type="mesh" contype="0" conaffinity="0" group="1" density="0" mesh="ability_right:FB_palm_ref_MIR"/>
                                    <geom name="ability_right:palm_hull" pos="-0.0240477 0.00378125 0.0323296" quat="0.0442297 0.00061027 -0.999021 -2.70192e-05" type="mesh" mesh="ability_right:palm_hull_mir"/>
                                    <body name="ability_right:index_L1" pos="-0.0279216 -0.00927034 0.0958706" quat="0.685906 0.0469401 -0.714459 -0.129917" gravcomp="0">
                                        <inertial pos="0.0224191 -0.000157982 -1.31987e-05" quat="-0.00406251 0.706621 0.00934715 0.707518" mass="0.00635888" diaginertia="3.81765e-06 3.69601e-06 2.96432e-07"/>
                                        <joint name="ability_right:index_q1" pos="0 0 0" axis="0 0 1" limited="true" range="0 2.0944" damping="0.001" frictionloss="0.001"/>
                                        <geom name="ability_right:index_mesh_1" pos="0.0384727 0.0032577 0" quat="0.999108 0 0 0.0422244" type="mesh" contype="0" conaffinity="0" group="1" density="0" mesh="ability_right:idx-F1"/>
                                        <geom name="ability_right:index_hull_1" pos="0.0384727 0.0032577 0" quat="0.999108 0 0 0.0422244" type="mesh" mesh="ability_right:idx-F1-hull"/>
                                        <body name="ability_right:index_L2" pos="0.0384727 0.0032577 0" quat="0.999108 0 0 0.0422244" gravcomp="0">
                                        <inertial pos="0.0133682 -0.00875392 -2.886e-05" quat="-0.161363 0.673074 0.216775 0.688434" mass="0.00645" diaginertia="2.64645e-06 2.63553e-06 1.71391e-07"/>
                                        <joint name="ability_right:index_q2" pos="0 0 0" axis="0 0 1" limited="true" range="0 2.6586" damping="0.001" frictionloss="0.001"/>
                                        <geom name="ability_right:index_mesh_2" pos="0.0091241 0 0" type="mesh" contype="0" conaffinity="0" group="1" density="0" mesh="ability_right:idx-F2"/>
                                        <geom name="ability_right:index_hull_2" pos="0.0091241 0 0" type="mesh" mesh="ability_right:idx-F2-hull"/>
                                        </body>
                                    </body>
                                    <body name="ability_right:middle_L1" pos="-0.00841718 -0.0115172 0.0990634" quat="0.704562 0.0715738 -0.698395 -0.103508" gravcomp="0">
                                        <inertial pos="0.0224191 -0.000157982 -1.31987e-05" quat="-0.00406251 0.706621 0.00934715 0.707518" mass="0.00635888" diaginertia="3.81765e-06 3.69601e-06 2.96432e-07"/>
                                        <joint name="ability_right:middle_q1" pos="0 0 0" axis="0 0 1" limited="true" range="0 2.0944" damping="0.001" frictionloss="0.001"/>
                                        <geom name="ability_right:middle_mesh_1" pos="0.0384727 0.0032577 0" quat="0.999108 0 0 0.0422244" type="mesh" contype="0" conaffinity="0" group="1" density="0" mesh="ability_right:idx-F1"/>
                                        <geom name="ability_right:middle_hull_1" pos="0.0384727 0.0032577 0" quat="0.999108 0 0 0.0422244" type="mesh" mesh="ability_right:idx-F1-hull"/>
                                        <body name="ability_right:middle_L2" pos="0.0384727 0.0032577 0" quat="0.999108 0 0 0.0422244" gravcomp="0">
                                        <inertial pos="0.0133682 -0.00875392 -2.886e-05" quat="-0.161363 0.673074 0.216775 0.688434" mass="0.00645" diaginertia="2.64645e-06 2.63553e-06 1.71391e-07"/>
                                        <joint name="ability_right:middle_q2" pos="0 0 0" axis="0 0 1" limited="true" range="0 2.6586" damping="0.001" frictionloss="0.001"/>
                                        <geom name="ability_right:middle_mesh_2" pos="0.0091241 0 0" type="mesh" contype="0" conaffinity="0" group="1" density="0" mesh="ability_right:idx-F2"/>
                                        <geom name="ability_right:middle_hull_2" pos="0.0091241 0 0" type="mesh" mesh="ability_right:idx-F2-hull"/>
                                        </body>
                                    </body>
                                    <body name="ability_right:ring_L1" pos="0.0117529 -0.0103946 0.0967038" quat="0.721351 0.0986547 -0.681173 -0.0769649" gravcomp="0">
                                        <inertial pos="0.0224191 -0.000157982 -1.31987e-05" quat="-0.00406251 0.706621 0.00934715 0.707518" mass="0.00635888" diaginertia="3.81765e-06 3.69601e-06 2.96432e-07"/>
                                        <joint name="ability_right:ring_q1" pos="0 0 0" axis="0 0 1" limited="true" range="0 2.0944" damping="0.001" frictionloss="0.001"/>
                                        <geom name="ability_right:ring_mesh_1" pos="0.0384727 0.0032577 0" quat="0.999108 0 0 0.0422244" type="mesh" contype="0" conaffinity="0" group="1" density="0" mesh="ability_right:idx-F1"/>
                                        <geom name="ability_right:ring_hull_1" pos="0.0384727 0.0032577 0" quat="0.999108 0 0 0.0422244" type="mesh" mesh="ability_right:idx-F1-hull"/>
                                        <body name="ability_right:ring_L2" pos="0.0384727 0.0032577 0" quat="0.999108 0 0 0.0422244" gravcomp="0">
                                        <inertial pos="0.0133682 -0.00875392 -2.886e-05" quat="-0.161363 0.673074 0.216775 0.688434" mass="0.00645" diaginertia="2.64645e-06 2.63553e-06 1.71391e-07"/>
                                        <joint name="ability_right:ring_q2" pos="0 0 0" axis="0 0 1" limited="true" range="0 2.6586" damping="0.001" frictionloss="0.001"/>
                                        <geom name="ability_right:ring_mesh_2" pos="0.0091241 0 0" type="mesh" contype="0" conaffinity="0" group="1" density="0" mesh="ability_right:idx-F2"/>
                                        <geom name="ability_right:ring_hull_2" pos="0.0091241 0 0" type="mesh" mesh="ability_right:idx-F2-hull"/>
                                        </body>
                                    </body>
                                    <body name="ability_right:pinky_L1" pos="0.0308633 -0.00716283 0.0907346" quat="0.719226 0.122363 -0.681748 -0.0544096" gravcomp="0">
                                        <inertial pos="0.0224191 -0.000157982 -1.31987e-05" quat="-0.00406251 0.706621 0.00934715 0.707518" mass="0.00635888" diaginertia="3.81765e-06 3.69601e-06 2.96432e-07"/>
                                        <joint name="ability_right:pinky_q1" pos="0 0 0" axis="0 0 1" limited="true" range="0 2.0944" damping="0.001" frictionloss="0.001"/>
                                        <geom name="ability_right:pinky_mesh_1" pos="0.0384727 0.0032577 0" quat="0.999108 0 0 0.0422244" type="mesh" contype="0" conaffinity="0" group="1" density="0" mesh="ability_right:idx-F1"/>
                                        <geom name="ability_right:pinky_hull_1" pos="0.0384727 0.0032577 0" quat="0.999108 0 0 0.0422244" type="mesh" mesh="ability_right:idx-F1-hull"/>
                                        <body name="ability_right:pinky_L2" pos="0.0384727 0.0032577 0" quat="0.999108 0 0 0.0422244" gravcomp="0">
                                        <inertial pos="0.0133682 -0.00875392 -2.886e-05" quat="-0.161363 0.673074 0.216775 0.688434" mass="0.00645" diaginertia="2.64645e-06 2.63553e-06 1.71391e-07"/>
                                        <joint name="ability_right:pinky_q2" pos="0 0 0" axis="0 0 1" limited="true" range="0 2.6586" damping="0.001" frictionloss="0.001"/>
                                        <geom name="ability_right:pinky_mesh_2" pos="0.0091241 0 0" type="mesh" contype="0" conaffinity="0" group="1" density="0" mesh="ability_right:idx-F2"/>
                                        <geom name="ability_right:pinky_hull_2" pos="0.0091241 0 0" type="mesh" mesh="ability_right:idx-F2-hull"/>
                                        </body>
                                    </body>
                                    <body name="ability_right:thumb_L1" pos="-0.0240477 0.00378125 0.0323296" quat="-0.0947972 0.0440301 -0.00419696 0.994514" gravcomp="0">
                                        <inertial pos="0.014606 -0.00189085 -0.00311554" quat="0.306728 0.531258 0.293089 0.733336" mass="0.00268342" diaginertia="8.14795e-07 7.42718e-07 1.14409e-07"/>
                                        <joint name="ability_right:thumb_q1" pos="0 0 0" axis="0 0 1" limited="true" range="-2.0944 0" damping="0.001" frictionloss="0.001"/>
                                        <geom name="ability_right:thumb_mesh_1" pos="0.0278284 0 0.0147507" quat="0.608761 0.793353 0 0" type="mesh" contype="0" conaffinity="0" group="1" density="0" mesh="ability_right:thumb-F1-MIR"/>
                                        <geom name="ability_right:thumb_hull_1" pos="0.0278284 0 0.0147507" quat="0.608761 0.793353 0 0" type="mesh" mesh="ability_right:thumb-F1-MIR-hull"/>
                                        <body name="ability_right:thumb_L2" pos="0.0278284 0 0.0147507" quat="0.608761 0.793353 0 0" gravcomp="0">
                                        <inertial pos="0.0300205 0.00559476 -0.00415044" quat="0.00721249 0.656735 -0.223684 0.720148" mass="0.0055" diaginertia="1.80207e-05 1.70892e-05 2.87855e-06"/>
                                        <joint name="ability_right:thumb_q2" pos="0 0 0" axis="0 0 1" limited="true" range="0 2.0944" damping="0.001" frictionloss="0.001"/>
                                        <geom name="ability_right:thumb_mesh_2" pos="0.0651867 0.0233402 0.00393483" quat="3.21978e-07 -0.985259 -0.171069 5.59046e-08" type="mesh" contype="0" conaffinity="0" group="1" density="0" mesh="ability_right:thumb-F2"/>
                                        <geom name="ability_right:thumb_hull_2" pos="0.0651867 0.0233402 0.00393483" quat="3.21978e-07 -0.985259 -0.171069 5.59046e-08" type="mesh" mesh="ability_right:thumb-F2-hull"/>
                                        </body>
                                    </body>
                                </body>
                            </body>
                        </body>
                    </body>
                </body>
            </body>
        </body>
    </body>
</mujoco>
